--- !ditz.rubyforge.org,2008-03-06/issue 
title: Print dlerror when loading library failed
desc: ""
type: :task
component: core
release: 
reporter: Sumi Tomohiko <SumiTomohiko@neko-daisuki.ddo.jp>
status: :closed
disposition: :wontfix
creation_time: 2010-05-20 12:11:59.037221 Z
references: []

id: e8bb1cf74e44c687f2344d95a826290d87d458bd
log_events: 
- - 2010-05-20 12:11:59.952056 Z
  - Sumi Tomohiko <SumiTomohiko@neko-daisuki.ddo.jp>
  - created
  - ""
- - 2010-06-18 08:56:12.825306 Z
  - Sumi Tomohiko <SumiTomohiko@neko-daisuki.ddo.jp>
  - commented
  - |-
    In the case of Python 3.1.2, Python does fopen at first of importing in
    Python/import.c. ImportError like "No module named foo" is raised at this point.
- - 2010-09-21 12:04:54.133128 Z
  - Sumi Tomohiko <SumiTomohiko@neko-daisuki.ddo.jp>
  - closed with disposition wontfix
  - Probably the --debug-import option realize this.
